Workbook
Name Slicer_Country: #N/A
Name Slicer_Industry: #N/A
Name Slicer_Start_Year: #N/A
Name Slicer_Subscription_Plan: #N/A

Sheet Subscription_Transactions
A1: Customer_ID | B1: Subscription_Plan | C1: Start_Date | D1: End_Date | E1: Monthly_Fee | F1: Status | G1: Acquisition_Channel | H1: Start_Month | I1: End_Month | J1: Country | K1: Industry | L1: Company_Size | M1: Start_Year
A2: C0001 | B2: Premium | C2: 43884 | D2: 45657 | E2: 40 | F2: Active | G2: LinkedIn | H2: =TEXT(C2,"mmm-yyyy") | I2: =TEXT(D2,"mmm-yyyy") | J2: =_xlfn.XLOOKUP(tbl_subscription[[#This Row],[Customer_ID]],tbl_clint[Customer_ID],tbl_clint[Country]) | K2: =_xlfn.XLOOKUP(tbl_subscription[[#This Row],[Customer_ID]],tbl_clint[[#This Row],[Customer_ID]],tbl_clint[[#This Row],[Industry]]) | L2: =_xlfn.XLOOKUP(tbl_subscription[[#This Row],[Customer_ID]],tbl_clint[[#This Row],[Customer_ID]],tbl_clint[[#This Row],[Company_Size]]) | M2: =YEAR(tbl_subscription[[#This Row],[Start_Date]])
A3: C0002 | B3: Basic | C3: 44092 | D3: 45657 | E3: 15 | F3: Active | G3: Instagram | H3: =TEXT(C3,"mmm-yyyy") | I3: =TEXT(D3,"mmm-yyyy") | J3: =_xlfn.XLOOKUP(tbl_subscription[[#This Row],[Customer_ID]],tbl_clint[Customer_ID],tbl_clint[Country]) | K3: =_xlfn.XLOOKUP(tbl_subscription[[#This Row],[Customer_ID]],tbl_clint[[#This Row],[Customer_ID]],tbl_clint[[#This Row],[Industry]]) | L3: =_xlfn.XLOOKUP(tbl_subscription[[#This Row],[Customer_ID]],tbl_clint[[#This Row],[Customer_ID]],tbl_clint[[#This Row],[Company_Size]]) | M3: =YEAR(tbl_subscription[[#This Row],[Start_Date]])
A4: C0003 | B4: Premium | C4: 44421 | D4: 44651 | E4: 40 | F4: Churned | G4: Facebook | H4: =TEXT(C4,"mmm-yyyy") | I4: =TEXT(D4,"mmm-yyyy") | J4: =_xlfn.XLOOKUP(tbl_subscription[[#This Row],[Customer_ID]],tbl_clint[Customer_ID],tbl_clint[Country]) | K4: =_xlfn.XLOOKUP(tbl_subscription[[#This Row],[Customer_ID]],tbl_clint[[#This Row],[Customer_ID]],tbl_clint[[#This Row],[Industry]]) | L4: =_xlfn.XLOOKUP(tbl_subscription[[#This Row],[Customer_ID]],tbl_clint[[#This Row],[Customer_ID]],tbl_clint[[#This Row],[Company_Size]]) | M4: =YEAR(tbl_subscription[[#This Row],[Start_Date]])
A5: C0004 | B5: Basic | C5: 44547 | D5: 45657 | E5: 15 | F5: Active | G5: Instagram | H5: =TEXT(C5,"mmm-yyyy") | I5: =TEXT(D5,"mmm-yyyy") | J5: =_xlfn.XLOOKUP(tbl_subscription[[#This Row],[Customer_ID]],tbl_clint[Customer_ID],tbl_clint[Country]) | K5: =_xlfn.XLOOKUP(tbl_subscription[[#This Row],[Customer_ID]],tbl_clint[[#This Row],[Customer_ID]],tbl_clint[[#This Row],[Industry]]) | L5: =_xlfn.XLOOKUP(tbl_subscription[[#This Row],[Customer_ID]],tbl_clint[[#This Row],[Customer_ID]],tbl_clint[[#This Row],[Company_Size]]) | M5: =YEAR(tbl_subscription[[#This Row],[Start_Date]])
A6: C0005 | B6: Standard | C6: 45091 | D6: 45657 | E6: 25 | F6: Active | G6: Referral | H6: =TEXT(C6,"mmm-yyyy") | I6: =TEXT(D6,"mmm-yyyy") | J6: =_xlfn.XLOOKUP(tbl_subscription[[#This Row],[Customer_ID]],tbl_clint[Customer_ID],tbl_clint[Country]) | K6: =_xlfn.XLOOKUP(tbl_subscription[[#This Row],[Customer_ID]],tbl_clint[[#This Row],[Customer_ID]],tbl_clint[[#This Row],[Industry]]) | L6: =_xlfn.XLOOKUP(tbl_subscription[[#This Row],[Customer_ID]],tbl_clint[[#This Row],[Customer_ID]],tbl_clint[[#This Row],[Company_Size]]) | M6: =YEAR(tbl_subscription[[#This Row],[Start_Date]])
A7: C0006 | B7: Basic | C7: 45425 | D7: 45615 | E7: 15 | F7: Churned | G7: LinkedIn | H7: =TEXT(C7,"mmm-yyyy") | I7: =TEXT(D7,"mmm-yyyy") | J7: =_xlfn.XLOOKUP(tbl_subscription[[#This Row],[Customer_ID]],tbl_clint[Customer_ID],tbl_clint[Country]) | K7: =_xlfn.XLOOKUP(tbl_subscription[[#This Row],[Customer_ID]],tbl_clint[[#This Row],[Customer_ID]],tbl_clint[[#This Row],[Industry]]) | L7: =_xlfn.XLOOKUP(tbl_subscription[[#This Row],[Customer_ID]],tbl_clint[[#This Row],[Customer_ID]],tbl_clint[[#This Row],[Company_Size]]) | M7: =YEAR(tbl_subscription[[#This Row],[Start_Date]])
A8: C0007 | B8: Standard | C8: 44060 | D8: 45657 | E8: 25 | F8: Active | G8: Facebook | H8: =TEXT(C8,"mmm-yyyy") | I8: =TEXT(D8,"mmm-yyyy") | J8: =_xlfn.XLOOKUP(tbl_subscription[[#This Row],[Customer_ID]],tbl_clint[Customer_ID],tbl_clint[Country]) | K8: =_xlfn.XLOOKUP(tbl_subscription[[#This Row],[Customer_ID]],tbl_clint[[#This Row],[Customer_ID]],tbl_clint[[#This Row],[Industry]]) | L8: =_xlfn.XLOOKUP(tbl_subscription[[#This Row],[Customer_ID]],tbl_clint[[#This Row],[Customer_ID]],tbl_clint[[#This Row],[Company_Size]]) | M8: =YEAR(tbl_subscription[[#This Row],[Start_Date]])
A9: C0008 | B9: Premium | C9: 45297 | D9: 45657 | E9: 40 | F9: Active | G9: Google | H9: =TEXT(C9,"mmm-yyyy") | I9: =TEXT(D9,"mmm-yyyy") | J9: =_xlfn.XLOOKUP(tbl_subscription[[#This Row],[Customer_ID]],tbl_clint[Customer_ID],tbl_clint[Country]) | K9: =_xlfn.XLOOKUP(tbl_subscription[[#This Row],[Customer_ID]],tbl_clint[[#This Row],[Customer_ID]],tbl_clint[[#This Row],[Industry]]) | L9: =_xlfn.XLOOKUP(tbl_subscription[[#This Row],[Customer_ID]],tbl_clint[[#This Row],[Customer_ID]],tbl_clint[[#This Row],[Company_Size]]) | M9: =YEAR(tbl_subscription[[#This Row],[Start_Date]])
A10: C0009 | B10: Premium | C10: 44403 | D10: 45657 | E10: 40 | F10: Active | G10: Referral | H10: =TEXT(C10,"mmm-yyyy") | I10: =TEXT(D10,"mmm-yyyy") | J10: =_xlfn.XLOOKUP(tbl_subscription[[#This Row],[Customer_ID]],tbl_clint[Customer_ID],tbl_clint[Country]) | K10: =_xlfn.XLOOKUP(tbl_subscription[[#This Row],[Customer_ID]],tbl_clint[[#This Row],[Customer_ID]],tbl_clint[[#This Row],[Industry]]) | L10: =_xlfn.XLOOKUP(tbl_subscription[[#This Row],[Customer_ID]],tbl_clint[[#This Row],[Customer_ID]],tbl_clint[[#This Row],[Company_Size]]) | M10: =YEAR(tbl_subscription[[#This Row],[Start_Date]])
A11: C0010 | B11: Premium | C11: 44491 | D11: 44607 | E11: 40 | F11: Churned | G11: Google | H11: =TEXT(C11,"mmm-yyyy") | I11: =TEXT(D11,"mmm-yyyy") | J11: =_xlfn.XLOOKUP(tbl_subscription[[#This Row],[Customer_ID]],tbl_clint[Customer_ID],tbl_clint[Country]) | K11: =_xlfn.XLOOKUP(tbl_subscription[[#This Row],[Customer_ID]],tbl_clint[[#This Row],[Customer_ID]],tbl_clint[[#This Row],[Industry]]) | L11: =_xlfn.XLOOKUP(tbl_subscription[[#This Row],[Customer_ID]],tbl_clint[[#This Row],[Customer_ID]],tbl_clint[[#This Row],[Company_Size]]) | M11: =YEAR(tbl_subscription[[#This Row],[Start_Date]])
A12: C0011 | B12: Standard | C12: 44289 | D12: 45657 | E12: 25 | F12: Active | G12: Facebook | H12: =TEXT(C12,"mmm-yyyy") | I12: =TEXT(D12,"mmm-yyyy") | J12: =_xlfn.XLOOKUP(tbl_subscription[[#This Row],[Customer_ID]],tbl_clint[Customer_ID],tbl_clint[Country]) | K12: =_xlfn.XLOOKUP(tbl_subscription[[#This Row],[Customer_ID]],tbl_clint[[#This Row],[Customer_ID]],tbl_clint[[#This Row],[Industry]]) | L12: =_xlfn.XLOOKUP(tbl_subscription[[#This Row],[Customer_ID]],tbl_clint[[#This Row],[Customer_ID]],tbl_clint[[#This Row],[Company_Size]]) | M12: =YEAR(tbl_subscription[[#This Row],[Start_Date]])
A13: C0012 | B13: Basic | C13: 45341 | D13: 45657 | E13: 15 | F13: Active | G13: Google | H13: =TEXT(C13,"mmm-yyyy") | I13: =TEXT(D13,"mmm-yyyy") | J13: =_xlfn.XLOOKUP(tbl_subscription[[#This Row],[Customer_ID]],tbl_clint[Customer_ID],tbl_clint[Country]) | K13: =_xlfn.XLOOKUP(tbl_subscription[[#This Row],[Customer_ID]],tbl_clint[[#This Row],[Customer_ID]],tbl_clint[[#This Row],[Industry]]) | L13: =_xlfn.XLOOKUP(tbl_subscription[[#This Row],[Customer_ID]],tbl_clint[[#This Row],[Customer_ID]],tbl_clint[[#This Row],[Company_Size]]) | M13: =YEAR(tbl_subscription[[#This Row],[Start_Date]])
... A801: C0800 | B801: Basic | C801: 45389 | D801: 45657 | E801: 15 | F801: Churned | G801: LinkedIn | H801: =TEXT(C801,"mmm-yyyy") | I801: =TEXT(D801,"mmm-yyyy") | J801: =_xlfn.XLOOKUP(tbl_subscription[[#This Row],[Customer_ID]],tbl_clint[Customer_ID],tbl_clint[Country]) | K801: =_xlfn.XLOOKUP(tbl_subscription[[#This Row],[Customer_ID]],tbl_clint[[#This Row],[Customer_ID]],tbl_clint[[#This Row],[Industry]]) | L801: =_xlfn.XLOOKUP(tbl_subscription[[#This Row],[Customer_ID]],tbl_clint[[#This Row],[Customer_ID]],tbl_clint[[#This Row],[Company_Size]]) | M801: =YEAR(tbl_subscription[[#This Row],[Start_Date]])

Sheet Client_Profile
A1: Customer_ID | B1: Country | C1: Industry | D1: Company_Size
A2: C0001 | B2: Sweden | C2: Finance | D2: Large
A3: C0002 | B3: Netherlands | C3: Finance | D3: Enterprise
A4: C0003 | B4: Germany | C4: Retail | D4: Small
A5: C0004 | B5: Italy | C5: Healthcare | D5: Enterprise
A6: C0005 | B6: France | C6: Education | D6: Large
A7: C0006 | B7: Italy | C7: Retail | D7: Medium
A8: C0007 | B8: Netherlands | C8: Tech | D8: Enterprise
A9: C0008 | B9: France | C9: Retail | D9: Large
A10: C0009 | B10: Germany | C10: E-commerce | D10: Small
A11: C0010 | B11: France | C11: E-commerce | D11: Large
A12: C0011 | B12: Spain | C12: Finance | D12: Small
... A801: C0800 | B801: Netherlands | C801: Finance | D801: Large

Sheet Revenue_Engine
A1: Total Customers | B1: =COUNTA(Subscription_Transactions!A2:A801) | F1: Row Labels | G1: Total Revenue | H1: Sum of Monthly_Fee
A2: Active Customers | B2: =COUNTIF(tbl_subscription[Status],"Active") | F2: 2020 | G2: 4860
A3: Churned Customers | B3: =COUNTIF(tbl_subscription[Status],"churned") | F3: 2021 | G3: 5485 | H3: 0.12860082
A4: Churn Rate | B4: =B3/B1 | F4: 2022 | G4: 4390 | H4: -0.096707819
A5: Active MRR | B5: =SUMIFS(Subscription_Transactions!E2:E801,Subscription_Transactions!F2:F801,"Active") | F5: 2023 | G5: 4110 | H5: -0.15432099
A6: ARPU | B6: =B5/B2 | F6: 2024 | G6: 2595 | H6: -0.46604938
A7: Total revenue | B7: =SUM(tbl_subscription[Monthly_Fee]) | F7: Grand Total | G7: 21440
A8: Avg YoY Growth | B8: =AVERAGE(E13:E16)
A9: Latest YoY (Selected Year) | B9: =E16
G10: Count of Customer_ID | H10: Column Labels
A11: Year | B11: Total Revenue | C11: Active Customers | D11: Churn Rate | E11: yoy growth | G11: Row Labels | H11: Active | I11: Churned | J11: Grand Total
A12: 2020 | B12: =SUMIFS(Subscription_Transactions!$E$2:$E$801,Subscription_Transactions!$M$2:$M$801,Revenue_Engine!A12) | C12: =COUNTIFS(Subscription_Transactions!$M$2:$M$801,Revenue_Engine!$A12,Subscription_Transactions!$F$2:$F$801,"Active") | D12: =COUNTIFS(Subscription_Transactions!$M:$M,Revenue_Engine!$A12,Subscription_Transactions!$F:$F,"Churned")/COUNTIF(Subscription_Transactions!$M:$M,$A12) | G12: 2020 | H12: 0.70391061 | I12: 0.29608939 | J12: 1
A13: 2021 | B13: =SUMIFS(Subscription_Transactions!$E$2:$E$801,Subscription_Transactions!$M$2:$M$801,Revenue_Engine!A13) | C13: =COUNTIFS(Subscription_Transactions!$M$2:$M$801,Revenue_Engine!$A13,Subscription_Transactions!$F$2:$F$801,"Active") | D13: =COUNTIFS(Subscription_Transactions!$M:$M,Revenue_Engine!$A13,Subscription_Transactions!$F:$F,"Churned")/COUNTIF(Subscription_Transactions!$M:$M,$A13) | E13: =(B13-B12)/B12 | G13: 2021 | H13: 0.64795918 | I13: 0.35204082 | J13: 1
A14: 2022 | B14: =SUMIFS(Subscription_Transactions!$E$2:$E$801,Subscription_Transactions!$M$2:$M$801,Revenue_Engine!A14) | C14: =COUNTIFS(Subscription_Transactions!$M$2:$M$801,Revenue_Engine!$A14,Subscription_Transactions!$F$2:$F$801,"Active") | D14: =COUNTIFS(Subscription_Transactions!$M:$M,Revenue_Engine!$A14,Subscription_Transactions!$F:$F,"Churned")/COUNTIF(Subscription_Transactions!$M:$M,$A14) | E14: =(B14-B13)/B13 | G14: 2022 | H14: 0.70520231 | I14: 0.29479769 | J14: 1
A15: 2023 | B15: =SUMIFS(Subscription_Transactions!$E$2:$E$801,Subscription_Transactions!$M$2:$M$801,Revenue_Engine!A15) | C15: =COUNTIFS(Subscription_Transactions!$M$2:$M$801,Revenue_Engine!$A15,Subscription_Transactions!$F$2:$F$801,"Active") | D15: =COUNTIFS(Subscription_Transactions!$M:$M,Revenue_Engine!$A15,Subscription_Transactions!$F:$F,"Churned")/COUNTIF(Subscription_Transactions!$M:$M,$A15) | E15: =(B15-B14)/B14 | G15: 2023 | H15: 0.65562914 | I15: 0.34437086 | J15: 1
A16: 2024 | B16: =SUMIFS(Subscription_Transactions!$E$2:$E$801,Subscription_Transactions!$M$2:$M$801,Revenue_Engine!A16) | C16: =COUNTIFS(Subscription_Transactions!$M$2:$M$801,Revenue_Engine!$A16,Subscription_Transactions!$F$2:$F$801,"Active") | D16: =COUNTIFS(Subscription_Transactions!$M:$M,Revenue_Engine!$A16,Subscription_Transactions!$F:$F,"Churned")/COUNTIF(Subscription_Transactions!$M:$M,$A16) | E16: =(B16-B15)/B15 | G16: 2024 | H16: 0.69306931 | I16: 0.30693069 | J16: 1
G17: Grand Total | H17: 0.68 | I17: 0.32 | J17: 1
F20: Row Labels | G20: Sum of Monthly_Fee | H20: Count of Customer_ID
F21: Basic | G21: 0.18260261 | H21: 261
F22: Premium | G22: 0.50373134 | H22: 270
F23: Standard | G23: 0.31366604 | H23: 269
F24: Grand Total | G24: 1 | H24: 800
F26: Row Labels | G26: Count of Customer_ID
F27: France | G27: 121
F28: Germany | G28: 132
F29: Italy | G29: 151
F30: Netherlands | G30: 143
F31: Spain | G31: 129
F32: Sweden | G32: 124
F33: Grand Total | G33: 800
F35: Row Labels | G35: Sum of Monthly_Fee
F36: France | G36: 0.15718284
F37: Germany | G37: 0.15951493
F38: Italy | G38: 0.18097015
F39: Netherlands | G39: 0.18773321
F40: Spain | G40: 0.16068097
F41: Sweden | G41: 0.15391791
F42: Grand Total | G42: 1
F44: Row Labels | G44: Count of Customer_ID
F45: Basic | G45: 261
...

Sheet Executive_Dashboard
